<?xml version="1.0" encoding="utf-8"?>
<!-- This URDF was automatically created by SolidWorks to URDF Exporter! Originally created by Stephen Brawner (brawner@gmail.com) 
     Commit Version: 1.6.0-4-g7f85cfe  Build Version: 1.6.7995.38578
     For more information, please see http://wiki.ros.org/sw_urdf_exporter -->
<robot
  name="agv_urdf">
  <link
    name="base_link">
    <inertial>
      <origin
        xyz="0.00879548020592815 0 -0.00224909454812159"
        rpy="0 0 0" />
      <mass
        value="287.973904356973" />
      <inertia
        ixx="34.2025325428659"
        ixy="8.56952940977074E-15"
        ixz="-0.134064779208868"
        iyy="101.117560253562"
        iyz="5.72265930242648E-16"
        izz="122.880210687156" />
    </inertial>
    <visual>
      <origin
        xyz="0 0 0"
        rpy="0 0 0" />
      <geometry>
        <mesh
          filename="package://agv_urdf/meshes/base_link.STL" />
      </geometry>
      <material
        name="">
        <color
          rgba="0.792156862745098 0.819607843137255 0.933333333333333 1" />
      </material>
    </visual>
    <collision>
      <origin
        xyz="0 0 0"
        rpy="0 0 0" />
      <geometry>
        <mesh
          filename="package://agv_urdf/meshes/base_link.STL" />
      </geometry>
    </collision>
  </link>
  <link
    name="steer_f_link">
    <inertial>
      <origin
        xyz="-0.00717555718342811 -0.0278525654563684 -0.044283884059445"
        rpy="0 0 0" />
      <mass
        value="26.0885663948635" />
      <inertia
        ixx="0.193845103804711"
        ixy="-0.00184343974656806"
        ixz="0.00379714309592857"
        iyy="0.194092909845274"
        iyz="-0.0442523017048679"
        izz="0.153445505801553" />
    </inertial>
    <visual>
      <origin
        xyz="0 0 0"
        rpy="0 0 0" />
      <geometry>
        <mesh
          filename="package://agv_urdf/meshes/steer_f_link.STL" />
      </geometry>
      <material
        name="">
        <color
          rgba="0.529411764705882 0.549019607843137 0.549019607843137 1" />
      </material>
    </visual>
    <collision>
      <origin
        xyz="0 0 0"
        rpy="0 0 0" />
      <geometry>
        <mesh
          filename="package://agv_urdf/meshes/steer_f_link.STL" />
      </geometry>
    </collision>
  </link>
  <joint
    name="steer_f_joint"
    type="continuous">
    <origin
      xyz="0.78 0.28 -0.219"
      rpy="0 0 0" />
    <parent
      link="base_link" />
    <child
      link="steer_f_link" />
    <axis
      xyz="0 0 1" />
    <limit
      lower="0.1"
      upper="1"
      effort="100"
      velocity="100" />
    <dynamics
      damping="0.1"
      friction="0.1" />
  </joint>
  <link
    name="traction_f_link">
    <inertial>
      <origin
        xyz="0 0 0.00540765020848077"
        rpy="0 0 0" />
      <mass
        value="48.2721089005952" />
      <inertia
        ixx="0.35604448663777"
        ixy="6.6317648394305E-18"
        ixz="7.79148194529945E-20"
        iyy="0.35604448663777"
        iyz="-3.4717407777933E-18"
        izz="0.266277291373223" />
    </inertial>
    <visual>
      <origin
        xyz="0 0 0"
        rpy="0 0 0" />
      <geometry>
        <mesh
          filename="package://agv_urdf/meshes/traction_f_link.STL" />
      </geometry>
      <material
        name="">
        <color
          rgba="0.529411764705882 0.549019607843137 0.549019607843137 1" />
      </material>
    </visual>
    <collision>
      <origin
        xyz="0 0 0"
        rpy="0 0 0" />
      <geometry>
        <mesh
          filename="package://agv_urdf/meshes/traction_f_link.STL" />
      </geometry>
    </collision>
  </link>
  <joint
    name="traction_f_joint"
    type="continuous">
    <origin
      xyz="0 -0.0005 -0.1808"
      rpy="1.5708 0 0" />
    <parent
      link="steer_f_link" />
    <child
      link="traction_f_link" />
    <axis
      xyz="0 0 1" />
    <limit
      lower="0.1"
      upper="1"
      effort="100"
      velocity="100" />
    <dynamics
      damping="0.1"
      friction="0.1" />
  </joint>
  <link
    name="castor_f_link">
    <inertial>
      <origin
        xyz="-0.0116716387839898 -4.44089209850063E-16 -0.0284449692331434"
        rpy="0 0 0" />
      <mass
        value="7.96892334713999" />
      <inertia
        ixx="0.0416073919894557"
        ixy="-1.06300246007598E-18"
        ixz="-0.0110442398178131"
        iyy="0.0422608740667285"
        iyz="1.2261569335218E-18"
        izz="0.0224352820122703" />
    </inertial>
    <visual>
      <origin
        xyz="0 0 0"
        rpy="0 0 0" />
      <geometry>
        <mesh
          filename="package://agv_urdf/meshes/castor_f_link.STL" />
      </geometry>
      <material
        name="">
        <color
          rgba="0.529411764705882 0.549019607843137 0.549019607843137 1" />
      </material>
    </visual>
    <collision>
      <origin
        xyz="0 0 0"
        rpy="0 0 0" />
      <geometry>
        <mesh
          filename="package://agv_urdf/meshes/castor_f_link.STL" />
      </geometry>
    </collision>
  </link>
  <joint
    name="castor_f_joint"
    type="continuous">
    <origin
      xyz="0.85459 -0.28 -0.2204"
      rpy="0 0 0" />
    <parent
      link="base_link" />
    <child
      link="castor_f_link" />
    <axis
      xyz="0 0 1" />
    <limit
      lower="0.1"
      upper="1"
      effort="100"
      velocity="100" />
    <dynamics
      damping="0.1"
      friction="0.1" />
  </joint>
  <link
    name="castor_f_w_link">
    <inertial>
      <origin
        xyz="1.11022302462516E-16 -5.55111512312578E-17 0"
        rpy="0 0 0" />
      <mass
        value="0.366852188066652" />
      <inertia
        ixx="0.00186124782211862"
        ixy="-5.01587969640318E-21"
        ixz="-4.46827755231372E-20"
        iyy="0.00186124782211862"
        iyz="5.1122589039438E-22"
        izz="0.00342739082507927" />
    </inertial>
    <visual>
      <origin
        xyz="0 0 0"
        rpy="0 0 0" />
      <geometry>
        <mesh
          filename="package://agv_urdf/meshes/castor_f_w_link.STL" />
      </geometry>
      <material
        name="">
        <color
          rgba="0.501960784313725 0.501960784313725 0.501960784313725 1" />
      </material>
    </visual>
    <collision>
      <origin
        xyz="0 0 0"
        rpy="0 0 0" />
      <geometry>
        <mesh
          filename="package://agv_urdf/meshes/castor_f_w_link.STL" />
      </geometry>
    </collision>
  </link>
  <joint
    name="castor_f_w_joint"
    type="continuous">
    <origin
      xyz="-0.07459 0 -0.1794"
      rpy="1.5708 0 0" />
    <parent
      link="castor_f_link" />
    <child
      link="castor_f_w_link" />
    <axis
      xyz="0 0 1" />
    <limit
      lower="0.1"
      upper="0.1"
      effort="100"
      velocity="100" />
    <dynamics
      damping="0.1"
      friction="0.1" />
  </joint>
  <link
    name="steer_b_link">
    <inertial>
      <origin
        xyz="0.00717555718342833 0.0278525654563677 -0.044283884059445"
        rpy="0 0 0" />
      <mass
        value="26.0885663948635" />
      <inertia
        ixx="0.193845103804712"
        ixy="-0.00184343974656803"
        ixz="-0.00379714309592856"
        iyy="0.194092909845275"
        iyz="0.0442523017048681"
        izz="0.153445505801553" />
    </inertial>
    <visual>
      <origin
        xyz="0 0 0"
        rpy="0 0 0" />
      <geometry>
        <mesh
          filename="package://agv_urdf/meshes/steer_b_link.STL" />
      </geometry>
      <material
        name="">
        <color
          rgba="0.529411764705882 0.549019607843137 0.549019607843137 1" />
      </material>
    </visual>
    <collision>
      <origin
        xyz="0 0 0"
        rpy="0 0 0" />
      <geometry>
        <mesh
          filename="package://agv_urdf/meshes/steer_b_link.STL" />
      </geometry>
    </collision>
  </link>
  <joint
    name="steer_b_joint"
    type="continuous">
    <origin
      xyz="-0.78 -0.28 -0.219"
      rpy="0 0 0" />
    <parent
      link="base_link" />
    <child
      link="steer_b_link" />
    <axis
      xyz="0 0 1" />
    <limit
      lower="0.1"
      upper="1"
      effort="100"
      velocity="100" />
    <dynamics
      damping="0.1"
      friction="0.1" />
  </joint>
  <link
    name="traction_b_link">
    <inertial>
      <origin
        xyz="1.11022302462516E-16 5.55111512312578E-17 -0.00540765020848033"
        rpy="0 0 0" />
      <mass
        value="48.2721089005952" />
      <inertia
        ixx="0.3560444866378"
        ixy="-1.17396581144442E-17"
        ixz="-4.58787554266472E-18"
        iyy="0.3560444866378"
        iyz="1.31824527773656E-17"
        izz="0.266277291373223" />
    </inertial>
    <visual>
      <origin
        xyz="0 0 0"
        rpy="0 0 0" />
      <geometry>
        <mesh
          filename="package://agv_urdf/meshes/traction_b_link.STL" />
      </geometry>
      <material
        name="">
        <color
          rgba="0.529411764705882 0.549019607843137 0.549019607843137 1" />
      </material>
    </visual>
    <collision>
      <origin
        xyz="0 0 0"
        rpy="0 0 0" />
      <geometry>
        <mesh
          filename="package://agv_urdf/meshes/traction_b_link.STL" />
      </geometry>
    </collision>
  </link>
  <joint
    name="traction_b_joint"
    type="continuous">
    <origin
      xyz="0 0.0005 -0.1808"
      rpy="1.5708 0 0" />
    <parent
      link="steer_b_link" />
    <child
      link="traction_b_link" />
    <axis
      xyz="0 0 1" />
    <limit
      lower="0.1"
      upper="1"
      effort="100"
      velocity="100" />
    <dynamics
      damping="0.1"
      friction="0.1" />
  </joint>
  <link
    name="castor_b_link">
    <inertial>
      <origin
        xyz="-0.0116716387839898 0 -0.0284449692331483"
        rpy="0 0 0" />
      <mass
        value="7.96892334714" />
      <inertia
        ixx="0.0416073919895143"
        ixy="2.45730336529973E-19"
        ixz="-0.0110442398178125"
        iyy="0.0422608740667871"
        iyz="2.90832919792927E-18"
        izz="0.0224352820122703" />
    </inertial>
    <visual>
      <origin
        xyz="0 0 0"
        rpy="0 0 0" />
      <geometry>
        <mesh
          filename="package://agv_urdf/meshes/castor_b_link.STL" />
      </geometry>
      <material
        name="">
        <color
          rgba="0.529411764705882 0.549019607843137 0.549019607843137 1" />
      </material>
    </visual>
    <collision>
      <origin
        xyz="0 0 0"
        rpy="0 0 0" />
      <geometry>
        <mesh
          filename="package://agv_urdf/meshes/castor_b_link.STL" />
      </geometry>
    </collision>
  </link>
  <joint
    name="castor_b_joint"
    type="continuous">
    <origin
      xyz="-0.70541 0.28 -0.2204"
      rpy="0 0 0" />
    <parent
      link="base_link" />
    <child
      link="castor_b_link" />
    <axis
      xyz="0 0 1" />
    <limit
      lower="0.1"
      upper="1"
      effort="100"
      velocity="100" />
    <dynamics
      damping="0.1"
      friction="0.1" />
  </joint>
  <link
    name="castor_b_w_link">
    <inertial>
      <origin
        xyz="0 5.55111512312578E-17 4.44089209850063E-16"
        rpy="0 0 0" />
      <mass
        value="0.366852188066652" />
      <inertia
        ixx="0.00186124782211861"
        ixy="-5.01587969640399E-21"
        ixz="2.5035980350045E-21"
        iyy="0.00186124782211861"
        iyz="5.11225890394175E-22"
        izz="0.00342739082507928" />
    </inertial>
    <visual>
      <origin
        xyz="0 0 0"
        rpy="0 0 0" />
      <geometry>
        <mesh
          filename="package://agv_urdf/meshes/castor_b_w_link.STL" />
      </geometry>
      <material
        name="">
        <color
          rgba="0.501960784313725 0.501960784313725 0.501960784313725 1" />
      </material>
    </visual>
    <collision>
      <origin
        xyz="0 0 0"
        rpy="0 0 0" />
      <geometry>
        <mesh
          filename="package://agv_urdf/meshes/castor_b_w_link.STL" />
      </geometry>
    </collision>
  </link>
  <joint
    name="castor_b_w_joint"
    type="continuous">
    <origin
      xyz="-0.07459 0 -0.1794"
      rpy="1.5708 0 0" />
    <parent
      link="castor_b_link" />
    <child
      link="castor_b_w_link" />
    <axis
      xyz="0 0 1" />
    <limit
      lower="0.1"
      upper="1"
      effort="100"
      velocity="100" />
    <dynamics
      damping="0.1"
      friction="0.1" />
  </joint>
  <link
    name="lidar_link">
    <inertial>
      <origin
        xyz="0 0 -0.00690172767252528"
        rpy="0 0 0" />
      <mass
        value="1.42972960856401" />
      <inertia
        ixx="0.000735367328208808"
        ixy="5.02540064106494E-20"
        ixz="4.40395213278562E-20"
        iyy="0.000735367328208806"
        iyz="-8.70508206688143E-19"
        izz="0.000854963034083045" />
    </inertial>
    <visual>
      <origin
        xyz="0 0 0"
        rpy="0 0 0" />
      <geometry>
        <mesh
          filename="package://agv_urdf/meshes/lidar_link.STL" />
      </geometry>
      <material
        name="">
        <color
          rgba="0.529411764705882 0.549019607843137 0.549019607843137 1" />
      </material>
    </visual>
    <collision>
      <origin
        xyz="0 0 0"
        rpy="0 0 0" />
      <geometry>
        <mesh
          filename="package://agv_urdf/meshes/lidar_link.STL" />
      </geometry>
    </collision>
  </link>
  <joint
    name="lidar_joint"
    type="fixed">
    <origin
      xyz="0.9675 0 0.0299999999999998"
      rpy="0 0 0" />
    <parent
      link="base_link" />
    <child
      link="lidar_link" />
    <axis
      xyz="0 0 0" />
  </joint>
</robot>