<?xml version='1.0' encoding='UTF-8'?>
<robot name="agv_urdf">
  <link name="base_link">
    <inertial>
      <origin xyz="0.00879548020592815 0.0 -0.00224909454812159" rpy="0.0 -0.0 0.0"/>
      <mass value="287.973904356973"/>
      <inertia ixx="34.2025325428659" ixy="8.56952940977074e-15" ixz="-0.134064779208868" iyy="101.117560253562" iyz="5.72265930242648e-16" izz="122.880210687156"/>
    </inertial>
    <visual>
      <geometry>
        <mesh filename="package://agv_urdf/meshes/base_link.dae"/>
      </geometry>
      <material name=""/>
      <origin xyz="0.0 0.0 0.0" rpy="0.0 -0.0 0.0"/>
    </visual>
    <collision>
      <geometry>
        <mesh filename="package://agv_urdf/meshes/base_link.dae"/>
      </geometry>
      <origin xyz="0.0 0.0 0.0" rpy="0.0 -0.0 0.0"/>
    </collision>
  </link>
  <link name="steer_f_link">
    <inertial>
      <origin xyz="-0.00717555718342811 -0.0278525654563684 -0.044283884059445" rpy="0.0 -0.0 0.0"/>
      <mass value="26.0885663948635"/>
      <inertia ixx="0.193845103804711" ixy="-0.00184343974656806" ixz="0.00379714309592857" iyy="0.194092909845274" iyz="-0.0442523017048679" izz="0.153445505801553"/>
    </inertial>
    <visual>
      <geometry>
        <mesh filename="package://agv_urdf/meshes/steer_f_link.dae"/>
      </geometry>
      <material name=""/>
      <origin xyz="0.0 0.0 0.0" rpy="0.0 -0.0 0.0"/>
    </visual>
    <collision>
      <geometry>
        <mesh filename="package://agv_urdf/meshes/steer_f_link.dae"/>
      </geometry>
      <origin xyz="0.0 0.0 0.0" rpy="0.0 -0.0 0.0"/>
    </collision>
  </link>
  <link name="traction_f_link">
    <inertial>
      <origin xyz="0.0 0.0 0.00540765020848077" rpy="0.0 -0.0 0.0"/>
      <mass value="48.2721089005952"/>
      <inertia ixx="0.35604448663777" ixy="6.6317648394305e-18" ixz="7.79148194529945e-20" iyy="0.35604448663777" iyz="-3.4717407777933e-18" izz="0.266277291373223"/>
    </inertial>
    <visual>
      <geometry>
        <mesh filename="package://agv_urdf/meshes/traction_f_link.dae"/>
      </geometry>
      <material name=""/>
      <origin xyz="0.0 0.0 0.0" rpy="0.0 -0.0 0.0"/>
    </visual>
    <collision>
      <geometry>
        <mesh filename="package://agv_urdf/meshes/traction_f_link.dae"/>
      </geometry>
      <origin xyz="0.0 0.0 0.0" rpy="0.0 -0.0 0.0"/>
    </collision>
  </link>
  <link name="castor_f_link">
    <inertial>
      <origin xyz="-0.0116716387839898 -4.44089209850063e-16 -0.0284449692331434" rpy="0.0 -0.0 0.0"/>
      <mass value="7.96892334713999"/>
      <inertia ixx="0.0416073919894557" ixy="-1.06300246007598e-18" ixz="-0.0110442398178131" iyy="0.0422608740667285" iyz="1.2261569335218e-18" izz="0.0224352820122703"/>
    </inertial>
    <visual>
      <geometry>
        <mesh filename="package://agv_urdf/meshes/castor_f_link.dae"/>
      </geometry>
      <material name=""/>
      <origin xyz="0.0 0.0 0.0" rpy="0.0 -0.0 0.0"/>
    </visual>
    <collision>
      <geometry>
        <mesh filename="package://agv_urdf/meshes/castor_f_link.dae"/>
      </geometry>
      <origin xyz="0.0 0.0 0.0" rpy="0.0 -0.0 0.0"/>
    </collision>
  </link>
  <link name="castor_f_w_link">
    <inertial>
      <origin xyz="1.11022302462516e-16 -5.55111512312578e-17 0.0" rpy="0.0 -0.0 0.0"/>
      <mass value="0.366852188066652"/>
      <inertia ixx="0.00186124782211862" ixy="-5.01587969640318e-21" ixz="-4.46827755231372e-20" iyy="0.00186124782211862" iyz="5.1122589039438e-22" izz="0.00342739082507927"/>
    </inertial>
    <visual>
      <geometry>
        <mesh filename="package://agv_urdf/meshes/castor_f_w_link.dae"/>
      </geometry>
      <material name=""/>
      <origin xyz="0.0 0.0 0.0" rpy="0.0 -0.0 0.0"/>
    </visual>
    <collision>
      <geometry>
        <mesh filename="package://agv_urdf/meshes/castor_f_w_link.dae"/>
      </geometry>
      <origin xyz="0.0 0.0 0.0" rpy="0.0 -0.0 0.0"/>
    </collision>
  </link>
  <link name="steer_b_link">
    <inertial>
      <origin xyz="0.00717555718342833 0.0278525654563677 -0.044283884059445" rpy="0.0 -0.0 0.0"/>
      <mass value="26.0885663948635"/>
      <inertia ixx="0.193845103804712" ixy="-0.00184343974656803" ixz="-0.00379714309592856" iyy="0.194092909845275" iyz="0.0442523017048681" izz="0.153445505801553"/>
    </inertial>
    <visual>
      <geometry>
        <mesh filename="package://agv_urdf/meshes/steer_b_link.dae"/>
      </geometry>
      <material name=""/>
      <origin xyz="0.0 0.0 0.0" rpy="0.0 -0.0 0.0"/>
    </visual>
    <collision>
      <geometry>
        <mesh filename="package://agv_urdf/meshes/steer_b_link.dae"/>
      </geometry>
      <origin xyz="0.0 0.0 0.0" rpy="0.0 -0.0 0.0"/>
    </collision>
  </link>
  <link name="traction_b_link">
    <inertial>
      <origin xyz="1.11022302462516e-16 5.55111512312578e-17 -0.00540765020848033" rpy="0.0 -0.0 0.0"/>
      <mass value="48.2721089005952"/>
      <inertia ixx="0.3560444866378" ixy="-1.17396581144442e-17" ixz="-4.58787554266472e-18" iyy="0.3560444866378" iyz="1.31824527773656e-17" izz="0.266277291373223"/>
    </inertial>
    <visual>
      <geometry>
        <mesh filename="package://agv_urdf/meshes/traction_b_link.dae"/>
      </geometry>
      <material name=""/>
      <origin xyz="0.0 0.0 0.0" rpy="0.0 -0.0 0.0"/>
    </visual>
    <collision>
      <geometry>
        <mesh filename="package://agv_urdf/meshes/traction_b_link.dae"/>
      </geometry>
      <origin xyz="0.0 0.0 0.0" rpy="0.0 -0.0 0.0"/>
    </collision>
  </link>
  <link name="castor_b_link">
    <inertial>
      <origin xyz="-0.0116716387839898 0.0 -0.0284449692331483" rpy="0.0 -0.0 0.0"/>
      <mass value="7.96892334714"/>
      <inertia ixx="0.0416073919895143" ixy="2.45730336529973e-19" ixz="-0.0110442398178125" iyy="0.0422608740667871" iyz="2.90832919792927e-18" izz="0.0224352820122703"/>
    </inertial>
    <visual>
      <geometry>
        <mesh filename="package://agv_urdf/meshes/castor_b_link.dae"/>
      </geometry>
      <material name=""/>
      <origin xyz="0.0 0.0 0.0" rpy="0.0 -0.0 0.0"/>
    </visual>
    <collision>
      <geometry>
        <mesh filename="package://agv_urdf/meshes/castor_b_link.dae"/>
      </geometry>
      <origin xyz="0.0 0.0 0.0" rpy="0.0 -0.0 0.0"/>
    </collision>
  </link>
  <link name="castor_b_w_link">
    <inertial>
      <origin xyz="0.0 5.55111512312578e-17 4.44089209850063e-16" rpy="0.0 -0.0 0.0"/>
      <mass value="0.366852188066652"/>
      <inertia ixx="0.00186124782211861" ixy="-5.01587969640399e-21" ixz="2.5035980350045e-21" iyy="0.00186124782211861" iyz="5.11225890394175e-22" izz="0.00342739082507928"/>
    </inertial>
    <visual>
      <geometry>
        <mesh filename="package://agv_urdf/meshes/castor_b_w_link.dae"/>
      </geometry>
      <material name=""/>
      <origin xyz="0.0 0.0 0.0" rpy="0.0 -0.0 0.0"/>
    </visual>
    <collision>
      <geometry>
        <mesh filename="package://agv_urdf/meshes/castor_b_w_link.dae"/>
      </geometry>
      <origin xyz="0.0 0.0 0.0" rpy="0.0 -0.0 0.0"/>
    </collision>
  </link>
  <link name="lidar_link">
    <inertial>
      <origin xyz="0.0 0.0 -0.00690172767252528" rpy="0.0 -0.0 0.0"/>
      <mass value="1.42972960856401"/>
      <inertia ixx="0.000735367328208808" ixy="5.02540064106494e-20" ixz="4.40395213278562e-20" iyy="0.000735367328208806" iyz="-8.70508206688143e-19" izz="0.000854963034083045"/>
    </inertial>
    <visual>
      <geometry>
        <mesh filename="package://agv_urdf/meshes/lidar_link.dae"/>
      </geometry>
      <material name=""/>
      <origin xyz="0.0 0.0 0.0" rpy="0.0 -0.0 0.0"/>
    </visual>
    <collision>
      <geometry>
        <mesh filename="package://agv_urdf/meshes/lidar_link.dae"/>
      </geometry>
      <origin xyz="0.0 0.0 0.0" rpy="0.0 -0.0 0.0"/>
    </collision>
  </link>
  <joint name="steer_f_joint" type="continuous">
    <dynamics damping="0.1" friction="0.1"/>
    <limit effort="100.0" velocity="100.0" lower="0.1" upper="1.0"/>
    <parent link="base_link"/>
    <child link="steer_f_link"/>
    <axis xyz="0. 0. 1."/>
    <origin xyz="0.78 0.28 -0.219" rpy="0.0 -0.0 0.0"/>
  </joint>
  <joint name="traction_f_joint" type="continuous">
    <dynamics damping="0.1" friction="0.1"/>
    <limit effort="100.0" velocity="100.0" lower="0.1" upper="1.0"/>
    <parent link="steer_f_link"/>
    <child link="traction_f_link"/>
    <axis xyz="0. 0. 1."/>
    <origin xyz="0.0 -0.0005 -0.1808" rpy="1.5708 -0.0 0.0"/>
  </joint>
  <joint name="castor_f_joint" type="continuous">
    <dynamics damping="0.1" friction="0.1"/>
    <limit effort="100.0" velocity="100.0" lower="0.1" upper="1.0"/>
    <parent link="base_link"/>
    <child link="castor_f_link"/>
    <axis xyz="0. 0. 1."/>
    <origin xyz="0.85459 -0.28 -0.2204" rpy="0.0 -0.0 0.0"/>
  </joint>
  <joint name="castor_f_w_joint" type="continuous">
    <dynamics damping="0.1" friction="0.1"/>
    <limit effort="100.0" velocity="100.0" lower="0.1" upper="0.1"/>
    <parent link="castor_f_link"/>
    <child link="castor_f_w_link"/>
    <axis xyz="0. 0. 1."/>
    <origin xyz="-0.07459 0.0 -0.1794" rpy="1.5708 -0.0 0.0"/>
  </joint>
  <joint name="steer_b_joint" type="continuous">
    <dynamics damping="0.1" friction="0.1"/>
    <limit effort="100.0" velocity="100.0" lower="0.1" upper="1.0"/>
    <parent link="base_link"/>
    <child link="steer_b_link"/>
    <axis xyz="0. 0. 1."/>
    <origin xyz="-0.78 -0.28 -0.219" rpy="0.0 -0.0 0.0"/>
  </joint>
  <joint name="traction_b_joint" type="continuous">
    <dynamics damping="0.1" friction="0.1"/>
    <limit effort="100.0" velocity="100.0" lower="0.1" upper="1.0"/>
    <parent link="steer_b_link"/>
    <child link="traction_b_link"/>
    <axis xyz="0. 0. 1."/>
    <origin xyz="0.0 0.0005 -0.1808" rpy="1.5708 -0.0 0.0"/>
  </joint>
  <joint name="castor_b_joint" type="continuous">
    <dynamics damping="0.1" friction="0.1"/>
    <limit effort="100.0" velocity="100.0" lower="0.1" upper="1.0"/>
    <parent link="base_link"/>
    <child link="castor_b_link"/>
    <axis xyz="0. 0. 1."/>
    <origin xyz="-0.70541 0.28 -0.2204" rpy="0.0 -0.0 0.0"/>
  </joint>
  <joint name="castor_b_w_joint" type="continuous">
    <dynamics damping="0.1" friction="0.1"/>
    <limit effort="100.0" velocity="100.0" lower="0.1" upper="1.0"/>
    <parent link="castor_b_link"/>
    <child link="castor_b_w_link"/>
    <axis xyz="0. 0. 1."/>
    <origin xyz="-0.07459 0.0 -0.1794" rpy="1.5708 -0.0 0.0"/>
  </joint>
  <joint name="lidar_joint" type="fixed">
    <limit effort="0.0" velocity="0.0"/>
    <parent link="base_link"/>
    <child link="lidar_link"/>
    <axis xyz="0. 0. 0."/>
    <origin xyz="0.9675 0.0 0.0299999999999998" rpy="0.0 -0.0 0.0"/>
  </joint>
  <material name="">
    <color rgba="0.79215686 0.81960784 0.93333333 1.        "/>
  </material>
</robot>
